[2024-10-27T19:57:44.661+0000] {taskinstance.py:1956} INFO - Dependencies all met for dep_context=non-requeueable deps ti=<TaskInstance: holiday_etl_pipeline.process_metrics scheduled__2024-10-26T00:00:00+00:00 [queued]>
[2024-10-27T19:57:44.670+0000] {taskinstance.py:1956} INFO - Dependencies all met for dep_context=requeueable deps ti=<TaskInstance: holiday_etl_pipeline.process_metrics scheduled__2024-10-26T00:00:00+00:00 [queued]>
[2024-10-27T19:57:44.671+0000] {taskinstance.py:2170} INFO - Starting attempt 2 of 2
[2024-10-27T19:57:44.682+0000] {taskinstance.py:2191} INFO - Executing <Task(_PythonDecoratedOperator): process_metrics> on 2024-10-26 00:00:00+00:00
[2024-10-27T19:57:44.688+0000] {standard_task_runner.py:60} INFO - Started process 734 to run task
[2024-10-27T19:57:44.691+0000] {standard_task_runner.py:87} INFO - Running: ['***', 'tasks', 'run', 'holiday_etl_pipeline', 'process_metrics', 'scheduled__2024-10-26T00:00:00+00:00', '--job-id', '29', '--raw', '--subdir', 'DAGS_FOLDER/holidays_orchestror.py', '--cfg-path', '/tmp/tmpbxteu929']
[2024-10-27T19:57:44.693+0000] {standard_task_runner.py:88} INFO - Job 29: Subtask process_metrics
[2024-10-27T19:57:44.737+0000] {task_command.py:423} INFO - Running <TaskInstance: holiday_etl_pipeline.process_metrics scheduled__2024-10-26T00:00:00+00:00 [running]> on host 09302ea91fa9
[2024-10-27T19:57:44.841+0000] {taskinstance.py:2480} INFO - Exporting env vars: AIRFLOW_CTX_DAG_OWNER='***' AIRFLOW_CTX_DAG_ID='holiday_etl_pipeline' AIRFLOW_CTX_TASK_ID='process_metrics' AIRFLOW_CTX_EXECUTION_DATE='2024-10-26T00:00:00+00:00' AIRFLOW_CTX_TRY_NUMBER='2' AIRFLOW_CTX_DAG_RUN_ID='scheduled__2024-10-26T00:00:00+00:00'
[2024-10-27T19:57:44.842+0000] {taskinstance.py:2698} ERROR - Task failed with exception
Traceback (most recent call last):
  File "/home/airflow/.local/lib/python3.11/site-packages/airflow/models/taskinstance.py", line 433, in _execute_task
    result = execute_callable(context=context, **execute_callable_kwargs)
             ^^^^^^^^^^^^^^^^^^^^^^^^^^^^^^^^^^^^^^^^^^^^^^^^^^^^^^^^^^^^
  File "/home/airflow/.local/lib/python3.11/site-packages/airflow/decorators/base.py", line 241, in execute
    return_value = super().execute(context)
                   ^^^^^^^^^^^^^^^^^^^^^^^^
  File "/home/airflow/.local/lib/python3.11/site-packages/airflow/operators/python.py", line 199, in execute
    return_value = self.execute_callable()
                   ^^^^^^^^^^^^^^^^^^^^^^^
  File "/home/airflow/.local/lib/python3.11/site-packages/airflow/operators/python.py", line 216, in execute_callable
    return self.python_callable(*self.op_args, **self.op_kwargs)
           ^^^^^^^^^^^^^^^^^^^^^^^^^^^^^^^^^^^^^^^^^^^^^^^^^^^^^
  File "/opt/airflow/dags/holidays_orchestror.py", line 82, in consolidate_metrics
    "total_records": landing_result["metrics"]["total_records"],
                     ~~~~~~~~~~~~~~^^^^^^^^^^^
TypeError: 'NoneType' object is not subscriptable
[2024-10-27T19:57:44.852+0000] {taskinstance.py:1138} INFO - Marking task as FAILED. dag_id=holiday_etl_pipeline, task_id=process_metrics, execution_date=20241026T000000, start_date=20241027T195744, end_date=20241027T195744
[2024-10-27T19:57:44.861+0000] {standard_task_runner.py:107} ERROR - Failed to execute job 29 for task process_metrics ('NoneType' object is not subscriptable; 734)
[2024-10-27T19:57:44.904+0000] {local_task_job_runner.py:234} INFO - Task exited with return code 1
[2024-10-27T19:57:44.917+0000] {taskinstance.py:3280} INFO - 0 downstream tasks scheduled from follow-on schedule check
[2024-10-27T20:36:10.756+0000] {taskinstance.py:1956} INFO - Dependencies all met for dep_context=non-requeueable deps ti=<TaskInstance: holiday_etl_pipeline.process_metrics scheduled__2024-10-26T00:00:00+00:00 [queued]>
[2024-10-27T20:36:10.761+0000] {taskinstance.py:1956} INFO - Dependencies all met for dep_context=requeueable deps ti=<TaskInstance: holiday_etl_pipeline.process_metrics scheduled__2024-10-26T00:00:00+00:00 [queued]>
[2024-10-27T20:36:10.762+0000] {taskinstance.py:2170} INFO - Starting attempt 2 of 2
[2024-10-27T20:36:10.770+0000] {taskinstance.py:2191} INFO - Executing <Task(_PythonDecoratedOperator): process_metrics> on 2024-10-26 00:00:00+00:00
[2024-10-27T20:36:10.774+0000] {standard_task_runner.py:60} INFO - Started process 302 to run task
[2024-10-27T20:36:10.776+0000] {standard_task_runner.py:87} INFO - Running: ['***', 'tasks', 'run', 'holiday_etl_pipeline', 'process_metrics', 'scheduled__2024-10-26T00:00:00+00:00', '--job-id', '6', '--raw', '--subdir', 'DAGS_FOLDER/holidays_orchestror.py', '--cfg-path', '/tmp/tmpck8ofbj4']
[2024-10-27T20:36:10.777+0000] {standard_task_runner.py:88} INFO - Job 6: Subtask process_metrics
[2024-10-27T20:36:10.807+0000] {task_command.py:423} INFO - Running <TaskInstance: holiday_etl_pipeline.process_metrics scheduled__2024-10-26T00:00:00+00:00 [running]> on host 85554215aad0
[2024-10-27T20:36:10.886+0000] {taskinstance.py:2480} INFO - Exporting env vars: AIRFLOW_CTX_DAG_OWNER='***' AIRFLOW_CTX_DAG_ID='holiday_etl_pipeline' AIRFLOW_CTX_TASK_ID='process_metrics' AIRFLOW_CTX_EXECUTION_DATE='2024-10-26T00:00:00+00:00' AIRFLOW_CTX_TRY_NUMBER='2' AIRFLOW_CTX_DAG_RUN_ID='scheduled__2024-10-26T00:00:00+00:00'
[2024-10-27T20:36:10.887+0000] {taskinstance.py:2698} ERROR - Task failed with exception
Traceback (most recent call last):
  File "/home/airflow/.local/lib/python3.11/site-packages/airflow/models/taskinstance.py", line 433, in _execute_task
    result = execute_callable(context=context, **execute_callable_kwargs)
             ^^^^^^^^^^^^^^^^^^^^^^^^^^^^^^^^^^^^^^^^^^^^^^^^^^^^^^^^^^^^
  File "/home/airflow/.local/lib/python3.11/site-packages/airflow/decorators/base.py", line 241, in execute
    return_value = super().execute(context)
                   ^^^^^^^^^^^^^^^^^^^^^^^^
  File "/home/airflow/.local/lib/python3.11/site-packages/airflow/operators/python.py", line 199, in execute
    return_value = self.execute_callable()
                   ^^^^^^^^^^^^^^^^^^^^^^^
  File "/home/airflow/.local/lib/python3.11/site-packages/airflow/operators/python.py", line 216, in execute_callable
    return self.python_callable(*self.op_args, **self.op_kwargs)
           ^^^^^^^^^^^^^^^^^^^^^^^^^^^^^^^^^^^^^^^^^^^^^^^^^^^^^
  File "/opt/airflow/dags/holidays_orchestror.py", line 82, in consolidate_metrics
    "total_records": landing_result["metrics"]["total_records"],
                     ~~~~~~~~~~~~~~^^^^^^^^^^^
TypeError: 'NoneType' object is not subscriptable
[2024-10-27T20:36:10.896+0000] {taskinstance.py:1138} INFO - Marking task as FAILED. dag_id=holiday_etl_pipeline, task_id=process_metrics, execution_date=20241026T000000, start_date=20241027T203610, end_date=20241027T203610
[2024-10-27T20:36:10.905+0000] {standard_task_runner.py:107} ERROR - Failed to execute job 6 for task process_metrics ('NoneType' object is not subscriptable; 302)
[2024-10-27T20:36:10.948+0000] {local_task_job_runner.py:234} INFO - Task exited with return code 1
[2024-10-27T20:36:10.960+0000] {taskinstance.py:3280} INFO - 0 downstream tasks scheduled from follow-on schedule check
